Workbook

Sheet Allocation
A1: Asset Class | B1: Region / Bucket | C1: Allocation % | D1: Derivation | E1: Default ETF | F1: ISIN | G1: Listing | H1: TER %
A2: Cash | B2: CHF | C2: =MAX(0.02,MIN(0.20,(10-10)*0.015+0)) -> 0.02 | D2: clamp((10−horizon) × 1.5 + 0, 2, 20) = 2%; capped by defensive sleeve | E2: (no ETF — cash sleeve) | F2: — | G2: —
A3: Fixed Income | B3: Global | C3: =1-0.6-C2-C9 -> 0.33 | D3: defensive(40) − cash(2) − gold(5) = 33% | E3: iShares Core Global Aggregate Bond UCITS | F3: IE00B3F81409 | G3: SIX: AGGH | H3: 0.001
A4: Equity | B4: USA | C4: =H14 -> 0.3652191 | D4: anchor 60% × (max(Sharpe,0.05)/0.25)^0.4 = 0.60 × 1.222 → 60.87% of equity sleeve × 60% equity = 36.52% | E4: iShares Core S&P 500 UCITS | F4: IE00B5BMR087 | G4: SIX: CSSPX | H4: 0.0007
A5: Equity | B5: EM | C5: =H18 -> 0.083175156 | D5: anchor 11% × (max(Sharpe,0.05)/0.25)^0.4 = 0.11 × 1.167 × 1.3 (horizon ≥ 10) → 13.86% of equity sleeve × 60% equity = 8.32% | E5: iShares Core MSCI EM IMI UCITS | F5: IE00BKM4GZ66 | G5: SIX: EIMI | H5: 0.0018
A6: Equity | B6: Switzerland | C6: =H16 -> 0.061934199 | D6: anchor 4% × (max(Sharpe,0.05)/0.25)^0.4 = 0.04 × 1.243 × home-bias 2.5 → 10.32% of equity sleeve × 60% equity = 6.19% | E6: iShares Core SPI | F6: CH0237935652 | G6: SIX: CHSPI | H6: 0.001
A7: Equity | B7: Europe | C7: =H15 -> 0.061172527 | D7: anchor 10% × (max(Sharpe,0.05)/0.25)^0.4 = 0.10 × 1.228 → 10.20% of equity sleeve × 60% equity = 6.12% | E7: iShares Core MSCI Europe UCITS | F7: IE00B4K48X80 | G7: SIX: CEU | H7: 0.0012
A8: Equity | B8: Japan | C8: =H17 -> 0.028499017 | D8: anchor 5% × (max(Sharpe,0.05)/0.25)^0.4 = 0.05 × 1.144 → 4.75% of equity sleeve × 60% equity = 2.85% | E8: iShares Core MSCI Japan IMI UCITS | F8: IE00B4L5YX21 | G8: SIX: CSJP | H8: 0.0012
A9: Commodities | B9: Gold | C9: =MIN(0.05,(1-0.6-C2)*0.15) -> 0.05 | D9: min(5, bonds(38) × 0.15 = 5.70) = 5.00%; subtracted from bonds | E9: Invesco Physical Gold ETC | F9: IE00B579F325 | G9: SIX: SGLD | H9: 0.0012
A10: Total | C10: =SUM(C2:C9) -> 1
A12: Equity Construction (this example) — anchor × POWER(MAX(Sharpe,0.05)/0.25, 0.4) × home-bias × EM tilt, normalised, × equity share (60%)
A13: Region | B13: Anchor | C13: Sharpe (live) | D13: Overlay | E13: Home-bias | F13: EM tilt | G13: Raw | H13: Normalised × 60%
A14: USA | B14: 0.6 | C14: ='CMA Assumptions'!E2 -> 0.4125 | D14: =POWER(MAX(C14,0.05)/0.25,0.4) -> 1.2217816 | E14: 1 | F14: 1 | G14: =B14*D14*E14*F14 -> 0.73306896 | H14: =G14/SUM(G14:G18)*0.6 -> 0.3652191
A15: Europe | B15: 0.1 | C15: ='CMA Assumptions'!E3 -> 0.41764706 | D15: =POWER(MAX(C15,0.05)/0.25,0.4) -> 1.2278569 | E15: 1 | F15: 1 | G15: =B15*D15*E15*F15 -> 0.12278569 | H15: =G15/SUM(G14:G18)*0.6 -> 0.061172527
A16: Switzerland | B16: 0.04 | C16: ='CMA Assumptions'!E5 -> 0.43076923 | D16: =POWER(MAX(C16,0.05)/0.25,0.4) -> 1.2431452 | E16: 2.5 | F16: 1 | G16: =B16*D16*E16*F16 -> 0.12431452 | H16: =G16/SUM(G14:G18)*0.6 -> 0.061934199
A17: Japan | B17: 0.05 | C17: ='CMA Assumptions'!E6 -> 0.35 | D17: =POWER(MAX(C17,0.05)/0.25,0.4) -> 1.1440664 | E17: 1 | F17: 1 | G17: =B17*D17*E17*F17 -> 0.057203318 | H17: =G17/SUM(G14:G18)*0.6 -> 0.028499017
A18: EM | B18: 0.11 | C18: ='CMA Assumptions'!E7 -> 0.36818182 | D18: =POWER(MAX(C18,0.05)/0.25,0.4) -> 1.1674786 | E18: 1 | F18: 1.3 | G18: =B18*D18*E18*F18 -> 0.16694944 | H18: =G18/SUM(G14:G18)*0.6 -> 0.083175156

Sheet CMA Assumptions
A1: Asset Key | B1: Label | C1: Expected Return μ | D1: Volatility σ | E1: Sharpe ((μ−Rf)/σ) | F1: Risk-Free Rate (CHF)
A2: equity_us | B2: US Equity | C2: 0.07 | D2: 0.16 | E2: =IF(D2>0,(C2-F2)/D2,0) -> 0.4125 | F2: 0.004
A3: equity_eu | B3: Europe Equity | C3: 0.075 | D3: 0.17 | E3: =IF(D3>0,(C3-F3)/D3,0) -> 0.41764706 | F3: 0.004
A4: equity_uk | B4: UK Equity | C4: 0.065 | D4: 0.15 | E4: =IF(D4>0,(C4-F4)/D4,0) -> 0.40666667 | F4: 0.004
A5: equity_ch | B5: Swiss Equity | C5: 0.06 | D5: 0.13 | E5: =IF(D5>0,(C5-F5)/D5,0) -> 0.43076923 | F5: 0.004
A6: equity_jp | B6: Japan Equity | C6: 0.06 | D6: 0.16 | E6: =IF(D6>0,(C6-F6)/D6,0) -> 0.35 | F6: 0.004
A7: equity_em | B7: EM Equity | C7: 0.085 | D7: 0.22 | E7: =IF(D7>0,(C7-F7)/D7,0) -> 0.36818182 | F7: 0.004
A8: equity_thematic | B8: Thematic Equity | C8: 0.08 | D8: 0.22 | E8: =IF(D8>0,(C8-F8)/D8,0) -> 0.34545455 | F8: 0.004
A9: equity_other | B9: Other / Residual | C9: 0.072 | D9: 0.17 | E9: =IF(D9>0,(C9-F9)/D9,0) -> 0.4 | F9: 0.004
A10: bonds | B10: Global Bonds | C10: 0.035 | D10: 0.06 | E10: =IF(D10>0,(C10-F10)/D10,0) -> 0.51666667 | F10: 0.004
A11: cash | B11: Cash | C11: 0.004 | D11: 0.005 | E11: =IF(D11>0,(C11-F11)/D11,0) -> 0 | F11: 0.004
A12: gold | B12: Gold | C12: 0.04 | D12: 0.16 | E12: =IF(D12>0,(C12-F12)/D12,0) -> 0.225 | F12: 0.004
A13: reits | B13: Listed Real Estate | C13: 0.065 | D13: 0.18 | E13: =IF(D13>0,(C13-F13)/D13,0) -> 0.33888889 | F13: 0.004
A14: crypto | B14: Crypto | C14: 0.12 | D14: 0.7 | E14: =IF(D14>0,(C14-F14)/D14,0) -> 0.16571429 | F14: 0.004

Sheet Correlations
A1: Asset | B1: equity_us | C1: equity_eu | D1: equity_uk | E1: equity_ch | F1: equity_jp | G1: equity_em | H1: equity_thematic | I1: equity_other | J1: bonds | K1: cash | L1: gold | M1: reits | N1: crypto
A2: equity_us | B2: 1 | C2: 0.82 | D2: 0.78 | E2: 0.7 | F2: 0.7 | G2: 0.72 | H2: 0.85 | I2: 0.85 | J2: 0.1 | K2: 0 | L2: 0.05 | M2: 0.7 | N2: 0.3
A3: equity_eu | B3: 0.82 | C3: 1 | D3: 0.85 | E3: 0.78 | F3: 0.65 | G3: 0.72 | H3: 0.78 | I3: 0.8 | J3: 0.1 | K3: 0 | L3: 0.05 | M3: 0.7 | N3: 0.28
A4: equity_uk | B4: 0.78 | C4: 0.85 | D4: 1 | E4: 0.72 | F4: 0.55 | G4: 0.62 | H4: 0.65 | I4: 0.75 | J4: 0.1 | K4: 0 | L4: 0.1 | M4: 0.65 | N4: 0.25
A5: equity_ch | B5: 0.7 | C5: 0.78 | D5: 0.72 | E5: 1 | F5: 0.55 | G5: 0.6 | H5: 0.65 | I5: 0.7 | J5: 0.15 | K5: 0 | L5: 0.1 | M5: 0.62 | N5: 0.2
A6: equity_jp | B6: 0.7 | C6: 0.65 | D6: 0.55 | E6: 0.55 | F6: 1 | G6: 0.6 | H6: 0.65 | I6: 0.7 | J6: 0.1 | K6: 0 | L6: 0.05 | M6: 0.55 | N6: 0.22
A7: equity_em | B7: 0.72 | C7: 0.72 | D7: 0.62 | E7: 0.6 | F7: 0.6 | G7: 1 | H7: 0.75 | I7: 0.75 | J7: 0.05 | K7: 0 | L7: 0.15 | M7: 0.65 | N7: 0.4
A8: equity_thematic | B8: 0.85 | C8: 0.78 | D8: 0.65 | E8: 0.65 | F8: 0.65 | G8: 0.75 | H8: 1 | I8: 0.8 | J8: 0.05 | K8: 0 | L8: 0.05 | M8: 0.65 | N8: 0.45
A9: equity_other | B9: 0.85 | C9: 0.8 | D9: 0.75 | E9: 0.7 | F9: 0.7 | G9: 0.75 | H9: 0.8 | I9: 1 | J9: 0.1 | K9: 0 | L9: 0.05 | M9: 0.65 | N9: 0.3
A10: bonds | B10: 0.1 | C10: 0.1 | D10: 0.1 | E10: 0.15 | F10: 0.1 | G10: 0.05 | H10: 0.05 | I10: 0.1 | J10: 1 | K10: 0.4 | L10: 0.2 | M10: 0.3 | N10: 0.05
A11: cash | B11: 0 | C11: 0 | D11: 0 | E11: 0 | F11: 0 | G11: 0 | H11: 0 | I11: 0 | J11: 0.4 | K11: 1 | L11: 0.05 | M11: 0 | N11: 0
A12: gold | B12: 0.05 | C12: 0.05 | D12: 0.1 | E12: 0.1 | F12: 0.05 | G12: 0.15 | H12: 0.05 | I12: 0.05 | J12: 0.2 | K12: 0.05 | L12: 1 | M12: 0.1 | N12: 0.2
A13: reits | B13: 0.7 | C13: 0.7 | D13: 0.65 | E13: 0.62 | F13: 0.55 | G13: 0.65 | H13: 0.65 | I13: 0.65 | J13: 0.3 | K13: 0 | L13: 0.1 | M13: 1 | N13: 0.3
A14: crypto | B14: 0.3 | C14: 0.28 | D14: 0.25 | E14: 0.2 | F14: 0.22 | G14: 0.4 | H14: 0.45 | I14: 0.3 | J14: 0.05 | K14: 0 | L14: 0.2 | M14: 0.3 | N14: 1

Sheet Look-through Exposures
A1: Asset Key | B1: Label | C1: Weight | D1: WHT Drag | E1: μ effective | F1: Benchmark Wt | G1: Derivation
A2: equity_us | B2: US Equity | C2: 0.3482856 | D2: 0.003 | E2: ='CMA Assumptions'!C2-D2 -> 0.067 | F2: 0.6 | G2: Equity-USA×United States 34.83%
A3: equity_eu | B3: Europe Equity | C3: 0.034526 | D3: 0.002 | E3: ='CMA Assumptions'!C3-D3 -> 0.073 | F3: 0.14 | G3: Equity-Europe×France 0.86% + Equity-Europe×Germany 0.83% + Equity-Europe×Netherlands 0.52% + Equity-Europe×Spain 0.33% + Equity-Europe×Italy 0.28% + Equity-Europe×Sweden 0.28% + Equity-Europe×Finland 0.10% + Equity-Europe×Denmark 0.10% + Equity-Europe×Belgium 0.08% + Equity-Europe×Norway 0.06%
A4: equity_uk | B4: UK Equity | C4: 0.0119621 | D4: 0.002 | E4: ='CMA Assumptions'!C4-D4 -> 0.063 | F4: 0.04 | G4: Equity-Europe×United Kingdom 1.20%
A5: equity_ch | B5: Swiss Equity | C5: 0.0568366 | D5: 0 | E5: ='CMA Assumptions'!C5-D5 -> 0.06 | F5: 0.04 | G5: Equity-Switzerland×Switzerland 4.93% + Equity-Europe×Switzerland 0.75%
A6: equity_jp | B6: Japan Equity | C6: 0.0281895 | D6: 0.002 | E6: ='CMA Assumptions'!C6-D6 -> 0.058 | F6: 0.04 | G6: Equity-EM×Hong Kong 0.10% + Equity-Japan×Japan 2.72%
A7: equity_em | B7: EM Equity | C7: 0.0719859 | D7: 0.004 | E7: ='CMA Assumptions'!C7-D7 -> 0.081 | F7: 0.14 | G7: Equity-EM×Taiwan 1.83% + Equity-EM×China 1.74% + Equity-EM×South Korea 1.26% + Equity-EM×India 0.96% + Equity-EM×Brazil 0.37% + Equity-EM×Saudi Arabia 0.25% + Equity-EM×South Africa 0.23% + Equity-EM×Mexico 0.15% + Equity-EM×Malaysia 0.12% + Equity-EM×Thailand 0.10% + Equity-EM×United Arab Emirates 0.10% + Equity-EM×Poland 0.09%
A8: equity_thematic | B8: Thematic Equity | C8: 0 | D8: 0.002 | E8: ='CMA Assumptions'!C8-D8 -> 0.078 | F8: 0 | G8: —
A9: equity_other | B9: Other / Residual | C9: 0.0482143 | D9: 0.0025 | E9: ='CMA Assumptions'!C9-D9 -> 0.0695 | F9: 0 | G9: Equity-USA unmapped 1.77% + Equity-EM unmapped 1.00% + Equity-Switzerland unmapped 1.27% + Equity-Europe unmapped 0.70% + Equity-Japan unmapped 0.08%
A10: bonds | B10: Global Bonds | C10: 0.33 | D10: 0 | E10: ='CMA Assumptions'!C10-D10 -> 0.035 | F10: 0 | G10: Fixed Income-Global 33.0%
A11: cash | B11: Cash | C11: 0.02 | D11: 0 | E11: ='CMA Assumptions'!F11-D11 -> 0.004 | F11: 0 | G11: Cash CHF 2.0%
A12: gold | B12: Gold | C12: 0.05 | D12: 0 | E12: ='CMA Assumptions'!C12-D12 -> 0.04 | F12: 0 | G12: Commodities-Gold 5.0%
A13: reits | B13: Listed Real Estate | C13: 0 | D13: 0 | E13: ='CMA Assumptions'!C13-D13 -> 0.065 | F13: 0 | G13: —
A14: crypto | B14: Crypto | C14: 0 | D14: 0 | E14: ='CMA Assumptions'!C14-D14 -> 0.12 | F14: 0 | G14: —
A15: Total | C15: =SUM(C2:C14) -> 1 | F15: =SUM(F2:F14) -> 1

Sheet _Covariance
A1: Σ_ij = σi·σj·ρij | B1: equity_us | C1: equity_eu | D1: equity_uk | E1: equity_ch | F1: equity_jp | G1: equity_em | H1: equity_thematic | I1: equity_other | J1: bonds | K1: cash | L1: gold | M1: reits | N1: crypto
A2: equity_us | B2: ='CMA Assumptions'!$D2*'CMA Assumptions'!$D2*Correlations!B2 -> 0.0256 | C2: ='CMA Assumptions'!$D2*'CMA Assumptions'!$D3*Correlations!C2 -> 0.022304 | D2: ='CMA Assumptions'!$D2*'CMA Assumptions'!$D4*Correlations!D2 -> 0.01872 | E2: ='CMA Assumptions'!$D2*'CMA Assumptions'!$D5*Correlations!E2 -> 0.01456 | F2: ='CMA Assumptions'!$D2*'CMA Assumptions'!$D6*Correlations!F2 -> 0.01792 | G2: ='CMA Assumptions'!$D2*'CMA Assumptions'!$D7*Correlations!G2 -> 0.025344 | H2: ='CMA Assumptions'!$D2*'CMA Assumptions'!$D8*Correlations!H2 -> 0.02992 | I2: ='CMA Assumptions'!$D2*'CMA Assumptions'!$D9*Correlations!I2 -> 0.02312 | J2: ='CMA Assumptions'!$D2*'CMA Assumptions'!$D10*Correlations!J2 -> 0.00096 | K2: ='CMA Assumptions'!$D2*'CMA Assumptions'!$D11*Correlations!K2 -> 0 | L2: ='CMA Assumptions'!$D2*'CMA Assumptions'!$D12*Correlations!L2 -> 0.00128 | M2: ='CMA Assumptions'!$D2*'CMA Assumptions'!$D13*Correlations!M2 -> 0.02016 | N2: ='CMA Assumptions'!$D2*'CMA Assumptions'!$D14*Correlations!N2 -> 0.0336
A3: equity_eu | B3: ='CMA Assumptions'!$D3*'CMA Assumptions'!$D2*Correlations!B3 -> 0.022304 | C3: ='CMA Assumptions'!$D3*'CMA Assumptions'!$D3*Correlations!C3 -> 0.0289 | D3: ='CMA Assumptions'!$D3*'CMA Assumptions'!$D4*Correlations!D3 -> 0.021675 | E3: ='CMA Assumptions'!$D3*'CMA Assumptions'!$D5*Correlations!E3 -> 0.017238 | F3: ='CMA Assumptions'!$D3*'CMA Assumptions'!$D6*Correlations!F3 -> 0.01768 | G3: ='CMA Assumptions'!$D3*'CMA Assumptions'!$D7*Correlations!G3 -> 0.026928 | H3: ='CMA Assumptions'!$D3*'CMA Assumptions'!$D8*Correlations!H3 -> 0.029172 | I3: ='CMA Assumptions'!$D3*'CMA Assumptions'!$D9*Correlations!I3 -> 0.02312 | J3: ='CMA Assumptions'!$D3*'CMA Assumptions'!$D10*Correlations!J3 -> 0.00102 | K3: ='CMA Assumptions'!$D3*'CMA Assumptions'!$D11*Correlations!K3 -> 0 | L3: ='CMA Assumptions'!$D3*'CMA Assumptions'!$D12*Correlations!L3 -> 0.00136 | M3: ='CMA Assumptions'!$D3*'CMA Assumptions'!$D13*Correlations!M3 -> 0.02142 | N3: ='CMA Assumptions'!$D3*'CMA Assumptions'!$D14*Correlations!N3 -> 0.03332
A4: equity_uk | B4: ='CMA Assumptions'!$D4*'CMA Assumptions'!$D2*Correlations!B4 -> 0.01872 | C4: ='CMA Assumptions'!$D4*'CMA Assumptions'!$D3*Correlations!C4 -> 0.021675 | D4: ='CMA Assumptions'!$D4*'CMA Assumptions'!$D4*Correlations!D4 -> 0.0225 | E4: ='CMA Assumptions'!$D4*'CMA Assumptions'!$D5*Correlations!E4 -> 0.01404 | F4: ='CMA Assumptions'!$D4*'CMA Assumptions'!$D6*Correlations!F4 -> 0.0132 | G4: ='CMA Assumptions'!$D4*'CMA Assumptions'!$D7*Correlations!G4 -> 0.02046 | H4: ='CMA Assumptions'!$D4*'CMA Assumptions'!$D8*Correlations!H4 -> 0.02145 | I4: ='CMA Assumptions'!$D4*'CMA Assumptions'!$D9*Correlations!I4 -> 0.019125 | J4: ='CMA Assumptions'!$D4*'CMA Assumptions'!$D10*Correlations!J4 -> 0.0009 | K4: ='CMA Assumptions'!$D4*'CMA Assumptions'!$D11*Correlations!K4 -> 0 | L4: ='CMA Assumptions'!$D4*'CMA Assumptions'!$D12*Correlations!L4 -> 0.0024 | M4: ='CMA Assumptions'!$D4*'CMA Assumptions'!$D13*Correlations!M4 -> 0.01755 | N4: ='CMA Assumptions'!$D4*'CMA Assumptions'!$D14*Correlations!N4 -> 0.02625
A5: equity_ch | B5: ='CMA Assumptions'!$D5*'CMA Assumptions'!$D2*Correlations!B5 -> 0.01456 | C5: ='CMA Assumptions'!$D5*'CMA Assumptions'!$D3*Correlations!C5 -> 0.017238 | D5: ='CMA Assumptions'!$D5*'CMA Assumptions'!$D4*Correlations!D5 -> 0.01404 | E5: ='CMA Assumptions'!$D5*'CMA Assumptions'!$D5*Correlations!E5 -> 0.0169 | F5: ='CMA Assumptions'!$D5*'CMA Assumptions'!$D6*Correlations!F5 -> 0.01144 | G5: ='CMA Assumptions'!$D5*'CMA Assumptions'!$D7*Correlations!G5 -> 0.01716 | H5: ='CMA Assumptions'!$D5*'CMA Assumptions'!$D8*Correlations!H5 -> 0.01859 | I5: ='CMA Assumptions'!$D5*'CMA Assumptions'!$D9*Correlations!I5 -> 0.01547 | J5: ='CMA Assumptions'!$D5*'CMA Assumptions'!$D10*Correlations!J5 -> 0.00117 | K5: ='CMA Assumptions'!$D5*'CMA Assumptions'!$D11*Correlations!K5 -> 0 | L5: ='CMA Assumptions'!$D5*'CMA Assumptions'!$D12*Correlations!L5 -> 0.00208 | M5: ='CMA Assumptions'!$D5*'CMA Assumptions'!$D13*Correlations!M5 -> 0.014508 | N5: ='CMA Assumptions'!$D5*'CMA Assumptions'!$D14*Correlations!N5 -> 0.0182
A6: equity_jp | B6: ='CMA Assumptions'!$D6*'CMA Assumptions'!$D2*Correlations!B6 -> 0.01792 | C6: ='CMA Assumptions'!$D6*'CMA Assumptions'!$D3*Correlations!C6 -> 0.01768 | D6: ='CMA Assumptions'!$D6*'CMA Assumptions'!$D4*Correlations!D6 -> 0.0132 | E6: ='CMA Assumptions'!$D6*'CMA Assumptions'!$D5*Correlations!E6 -> 0.01144 | F6: ='CMA Assumptions'!$D6*'CMA Assumptions'!$D6*Correlations!F6 -> 0.0256 | G6: ='CMA Assumptions'!$D6*'CMA Assumptions'!$D7*Correlations!G6 -> 0.02112 | H6: ='CMA Assumptions'!$D6*'CMA Assumptions'!$D8*Correlations!H6 -> 0.02288 | I6: ='CMA Assumptions'!$D6*'CMA Assumptions'!$D9*Correlations!I6 -> 0.01904 | J6: ='CMA Assumptions'!$D6*'CMA Assumptions'!$D10*Correlations!J6 -> 0.00096 | K6: ='CMA Assumptions'!$D6*'CMA Assumptions'!$D11*Correlations!K6 -> 0 | L6: ='CMA Assumptions'!$D6*'CMA Assumptions'!$D12*Correlations!L6 -> 0.00128 | M6: ='CMA Assumptions'!$D6*'CMA Assumptions'!$D13*Correlations!M6 -> 0.01584 | N6: ='CMA Assumptions'!$D6*'CMA Assumptions'!$D14*Correlations!N6 -> 0.02464
A7: equity_em | B7: ='CMA Assumptions'!$D7*'CMA Assumptions'!$D2*Correlations!B7 -> 0.025344 | C7: ='CMA Assumptions'!$D7*'CMA Assumptions'!$D3*Correlations!C7 -> 0.026928 | D7: ='CMA Assumptions'!$D7*'CMA Assumptions'!$D4*Correlations!D7 -> 0.02046 | E7: ='CMA Assumptions'!$D7*'CMA Assumptions'!$D5*Correlations!E7 -> 0.01716 | F7: ='CMA Assumptions'!$D7*'CMA Assumptions'!$D6*Correlations!F7 -> 0.02112 | G7: ='CMA Assumptions'!$D7*'CMA Assumptions'!$D7*Correlations!G7 -> 0.0484 | H7: ='CMA Assumptions'!$D7*'CMA Assumptions'!$D8*Correlations!H7 -> 0.0363 | I7: ='CMA Assumptions'!$D7*'CMA Assumptions'!$D9*Correlations!I7 -> 0.02805 | J7: ='CMA Assumptions'!$D7*'CMA Assumptions'!$D10*Correlations!J7 -> 0.00066 | K7: ='CMA Assumptions'!$D7*'CMA Assumptions'!$D11*Correlations!K7 -> 0 | L7: ='CMA Assumptions'!$D7*'CMA Assumptions'!$D12*Correlations!L7 -> 0.00528 | M7: ='CMA Assumptions'!$D7*'CMA Assumptions'!$D13*Correlations!M7 -> 0.02574 | N7: ='CMA Assumptions'!$D7*'CMA Assumptions'!$D14*Correlations!N7 -> 0.0616
A8: equity_thematic | B8: ='CMA Assumptions'!$D8*'CMA Assumptions'!$D2*Correlations!B8 -> 0.02992 | C8: ='CMA Assumptions'!$D8*'CMA Assumptions'!$D3*Correlations!C8 -> 0.029172 | D8: ='CMA Assumptions'!$D8*'CMA Assumptions'!$D4*Correlations!D8 -> 0.02145 | E8: ='CMA Assumptions'!$D8*'CMA Assumptions'!$D5*Correlations!E8 -> 0.01859 | F8: ='CMA Assumptions'!$D8*'CMA Assumptions'!$D6*Correlations!F8 -> 0.02288 | G8: ='CMA Assumptions'!$D8*'CMA Assumptions'!$D7*Correlations!G8 -> 0.0363 | H8: ='CMA Assumptions'!$D8*'CMA Assumptions'!$D8*Correlations!H8 -> 0.0484 | I8: ='CMA Assumptions'!$D8*'CMA Assumptions'!$D9*Correlations!I8 -> 0.02992 | J8: ='CMA Assumptions'!$D8*'CMA Assumptions'!$D10*Correlations!J8 -> 0.00066 | K8: ='CMA Assumptions'!$D8*'CMA Assumptions'!$D11*Correlations!K8 -> 0 | L8: ='CMA Assumptions'!$D8*'CMA Assumptions'!$D12*Correlations!L8 -> 0.00176 | M8: ='CMA Assumptions'!$D8*'CMA Assumptions'!$D13*Correlations!M8 -> 0.02574 | N8: ='CMA Assumptions'!$D8*'CMA Assumptions'!$D14*Correlations!N8 -> 0.0693
A9: equity_other | B9: ='CMA Assumptions'!$D9*'CMA Assumptions'!$D2*Correlations!B9 -> 0.02312 | C9: ='CMA Assumptions'!$D9*'CMA Assumptions'!$D3*Correlations!C9 -> 0.02312 | D9: ='CMA Assumptions'!$D9*'CMA Assumptions'!$D4*Correlations!D9 -> 0.019125 | E9: ='CMA Assumptions'!$D9*'CMA Assumptions'!$D5*Correlations!E9 -> 0.01547 | F9: ='CMA Assumptions'!$D9*'CMA Assumptions'!$D6*Correlations!F9 -> 0.01904 | G9: ='CMA Assumptions'!$D9*'CMA Assumptions'!$D7*Correlations!G9 -> 0.02805 | H9: ='CMA Assumptions'!$D9*'CMA Assumptions'!$D8*Correlations!H9 -> 0.02992 | I9: ='CMA Assumptions'!$D9*'CMA Assumptions'!$D9*Correlations!I9 -> 0.0289 | J9: ='CMA Assumptions'!$D9*'CMA Assumptions'!$D10*Correlations!J9 -> 0.00102 | K9: ='CMA Assumptions'!$D9*'CMA Assumptions'!$D11*Correlations!K9 -> 0 | L9: ='CMA Assumptions'!$D9*'CMA Assumptions'!$D12*Correlations!L9 -> 0.00136 | M9: ='CMA Assumptions'!$D9*'CMA Assumptions'!$D13*Correlations!M9 -> 0.01989 | N9: ='CMA Assumptions'!$D9*'CMA Assumptions'!$D14*Correlations!N9 -> 0.0357
A10: bonds | B10: ='CMA Assumptions'!$D10*'CMA Assumptions'!$D2*Correlations!B10 -> 0.00096 | C10: ='CMA Assumptions'!$D10*'CMA Assumptions'!$D3*Correlations!C10 -> 0.00102 | D10: ='CMA Assumptions'!$D10*'CMA Assumptions'!$D4*Correlations!D10 -> 0.0009 | E10: ='CMA Assumptions'!$D10*'CMA Assumptions'!$D5*Correlations!E10 -> 0.00117 | F10: ='CMA Assumptions'!$D10*'CMA Assumptions'!$D6*Correlations!F10 -> 0.00096 | G10: ='CMA Assumptions'!$D10*'CMA Assumptions'!$D7*Correlations!G10 -> 0.00066 | H10: ='CMA Assumptions'!$D10*'CMA Assumptions'!$D8*Correlations!H10 -> 0.00066 | I10: ='CMA Assumptions'!$D10*'CMA Assumptions'!$D9*Correlations!I10 -> 0.00102 | J10: ='CMA Assumptions'!$D10*'CMA Assumptions'!$D10*Correlations!J10 -> 0.0036 | K10: ='CMA Assumptions'!$D10*'CMA Assumptions'!$D11*Correlations!K10 -> 0.00012 | L10: ='CMA Assumptions'!$D10*'CMA Assumptions'!$D12*Correlations!L10 -> 0.00192 | M10: ='CMA Assumptions'!$D10*'CMA Assumptions'!$D13*Correlations!M10 -> 0.00324 | N10: ='CMA Assumptions'!$D10*'CMA Assumptions'!$D14*Correlations!N10 -> 0.0021
A11: cash | B11: ='CMA Assumptions'!$D11*'CMA Assumptions'!$D2*Correlations!B11 -> 0 | C11: ='CMA Assumptions'!$D11*'CMA Assumptions'!$D3*Correlations!C11 -> 0 | D11: ='CMA Assumptions'!$D11*'CMA Assumptions'!$D4*Correlations!D11 -> 0 | E11: ='CMA Assumptions'!$D11*'CMA Assumptions'!$D5*Correlations!E11 -> 0 | F11: ='CMA Assumptions'!$D11*'CMA Assumptions'!$D6*Correlations!F11 -> 0 | G11: ='CMA Assumptions'!$D11*'CMA Assumptions'!$D7*Correlations!G11 -> 0 | H11: ='CMA Assumptions'!$D11*'CMA Assumptions'!$D8*Correlations!H11 -> 0 | I11: ='CMA Assumptions'!$D11*'CMA Assumptions'!$D9*Correlations!I11 -> 0 | J11: ='CMA Assumptions'!$D11*'CMA Assumptions'!$D10*Correlations!J11 -> 0.00012 | K11: ='CMA Assumptions'!$D11*'CMA Assumptions'!$D11*Correlations!K11 -> 2.5e-05 | L11: ='CMA Assumptions'!$D11*'CMA Assumptions'!$D12*Correlations!L11 -> 4e-05 | M11: ='CMA Assumptions'!$D11*'CMA Assumptions'!$D13*Correlations!M11 -> 0 | N11: ='CMA Assumptions'!$D11*'CMA Assumptions'!$D14*Correlations!N11 -> 0
A12: gold | B12: ='CMA Assumptions'!$D12*'CMA Assumptions'!$D2*Correlations!B12 -> 0.00128 | C12: ='CMA Assumptions'!$D12*'CMA Assumptions'!$D3*Correlations!C12 -> 0.00136 | D12: ='CMA Assumptions'!$D12*'CMA Assumptions'!$D4*Correlations!D12 -> 0.0024 | E12: ='CMA Assumptions'!$D12*'CMA Assumptions'!$D5*Correlations!E12 -> 0.00208 | F12: ='CMA Assumptions'!$D12*'CMA Assumptions'!$D6*Correlations!F12 -> 0.00128 | G12: ='CMA Assumptions'!$D12*'CMA Assumptions'!$D7*Correlations!G12 -> 0.00528 | H12: ='CMA Assumptions'!$D12*'CMA Assumptions'!$D8*Correlations!H12 -> 0.00176 | I12: ='CMA Assumptions'!$D12*'CMA Assumptions'!$D9*Correlations!I12 -> 0.00136 | J12: ='CMA Assumptions'!$D12*'CMA Assumptions'!$D10*Correlations!J12 -> 0.00192 | K12: ='CMA Assumptions'!$D12*'CMA Assumptions'!$D11*Correlations!K12 -> 4e-05 | L12: ='CMA Assumptions'!$D12*'CMA Assumptions'!$D12*Correlations!L12 -> 0.0256 | M12: ='CMA Assumptions'!$D12*'CMA Assumptions'!$D13*Correlations!M12 -> 0.00288 | N12: ='CMA Assumptions'!$D12*'CMA Assumptions'!$D14*Correlations!N12 -> 0.0224
A13: reits | B13: ='CMA Assumptions'!$D13*'CMA Assumptions'!$D2*Correlations!B13 -> 0.02016 | C13: ='CMA Assumptions'!$D13*'CMA Assumptions'!$D3*Correlations!C13 -> 0.02142 | D13: ='CMA Assumptions'!$D13*'CMA Assumptions'!$D4*Correlations!D13 -> 0.01755 | E13: ='CMA Assumptions'!$D13*'CMA Assumptions'!$D5*Correlations!E13 -> 0.014508 | F13: ='CMA Assumptions'!$D13*'CMA Assumptions'!$D6*Correlations!F13 -> 0.01584 | G13: ='CMA Assumptions'!$D13*'CMA Assumptions'!$D7*Correlations!G13 -> 0.02574 | H13: ='CMA Assumptions'!$D13*'CMA Assumptions'!$D8*Correlations!H13 -> 0.02574 | I13: ='CMA Assumptions'!$D13*'CMA Assumptions'!$D9*Correlations!I13 -> 0.01989 | J13: ='CMA Assumptions'!$D13*'CMA Assumptions'!$D10*Correlations!J13 -> 0.00324 | K13: ='CMA Assumptions'!$D13*'CMA Assumptions'!$D11*Correlations!K13 -> 0 | L13: ='CMA Assumptions'!$D13*'CMA Assumptions'!$D12*Correlations!L13 -> 0.00288 | M13: ='CMA Assumptions'!$D13*'CMA Assumptions'!$D13*Correlations!M13 -> 0.0324 | N13: ='CMA Assumptions'!$D13*'CMA Assumptions'!$D14*Correlations!N13 -> 0.0378
A14: crypto | B14: ='CMA Assumptions'!$D14*'CMA Assumptions'!$D2*Correlations!B14 -> 0.0336 | C14: ='CMA Assumptions'!$D14*'CMA Assumptions'!$D3*Correlations!C14 -> 0.03332 | D14: ='CMA Assumptions'!$D14*'CMA Assumptions'!$D4*Correlations!D14 -> 0.02625 | E14: ='CMA Assumptions'!$D14*'CMA Assumptions'!$D5*Correlations!E14 -> 0.0182 | F14: ='CMA Assumptions'!$D14*'CMA Assumptions'!$D6*Correlations!F14 -> 0.02464 | G14: ='CMA Assumptions'!$D14*'CMA Assumptions'!$D7*Correlations!G14 -> 0.0616 | H14: ='CMA Assumptions'!$D14*'CMA Assumptions'!$D8*Correlations!H14 -> 0.0693 | I14: ='CMA Assumptions'!$D14*'CMA Assumptions'!$D9*Correlations!I14 -> 0.0357 | J14: ='CMA Assumptions'!$D14*'CMA Assumptions'!$D10*Correlations!J14 -> 0.0021 | K14: ='CMA Assumptions'!$D14*'CMA Assumptions'!$D11*Correlations!K14 -> 0 | L14: ='CMA Assumptions'!$D14*'CMA Assumptions'!$D12*Correlations!L14 -> 0.0224 | M14: ='CMA Assumptions'!$D14*'CMA Assumptions'!$D13*Correlations!M14 -> 0.0378 | N14: ='CMA Assumptions'!$D14*'CMA Assumptions'!$D14*Correlations!N14 -> 0.49

Sheet Risk & Performance
A1: Metric | B1: Value | C1: Formula / Note
A2: Building blocks (live formulas)
A3: Portfolio gross variance (σ_p²) | B3: =SUMPRODUCT('Look-through Exposures'!C2:C14,MMULT(_Covariance!B2:N14,'Look-through Exposures'!C2:C14)) -> 0.0092239026 | C3: wᵖ' Σ wᵖ — quadratic form using the covariance sheet.
A4: Benchmark gross variance (σ_B²) | B4: =SUMPRODUCT('Look-through Exposures'!F2:F14,MMULT(_Covariance!B2:N14,'Look-through Exposures'!F2:F14)) -> 0.023768627 | C4: wᴮ' Σ wᴮ — ACWI proxy benchmark from BENCHMARK in metrics.ts.
A5: Cov(portfolio, benchmark) | B5: =SUMPRODUCT('Look-through Exposures'!C2:C14,MMULT(_Covariance!B2:N14,'Look-through Exposures'!F2:F14)) -> 0.014349194 | C5: wᵖ' Σ wᴮ — needed for β and tracking error.
A6: Equity share (incl. REITs + Crypto) | B6: =SUM('Look-through Exposures'!C2:C9)+'Look-through Exposures'!C13+'Look-through Exposures'!C14 -> 0.6 | C6: Used by the heuristic max-drawdown formula.
A7: Risk-free rate (CHF, decimal) | B7: ='CMA Assumptions'!F2 -> 0.004
A8: Risk & Performance Metrics (live formulas)
A9: Expected Return (net of WHT) | B9: =SUMPRODUCT('Look-through Exposures'!C2:C14,'Look-through Exposures'!E2:E14) -> 0.054466084 | C9: Σ wᵢ · μᵢ_effective. Cash sleeve uses Rf_CHF for μ; equity rows are CMA μ minus WHT drag (CHF resident: equity_ch WHT = 0).
A10: Volatility (σ_p) | B10: =SQRT(MAX(SUMPRODUCT('Look-through Exposures'!C2:C14,MMULT(_Covariance!B2:N14,'Look-through Exposures'!C2:C14)),0)) -> 0.09604115 | C10: √(wᵖ' Σ wᵖ). Normal-regime correlations.
A11: Sharpe Ratio | B11: =IF(SQRT(MAX(SUMPRODUCT('Look-through Exposures'!C2:C14,MMULT(_Covariance!B2:N14,'Look-through Exposures'!C2:C14)),0))>0,(SUMPRODUCT('Look-through Exposures'!C2:C14,'Look-through Exposures'!E2:E14)-'CMA Assumptions'!F2)/SQRT(MAX(SUMPRODUCT('Look-through Exposures'!C2:C14,MMULT(_Covariance!B2:N14,'Look-through Exposures'!C2:C14)),0)),0) -> 0.52546314 | C11: (μ_p − Rf) / σ_p with Rf = CHF risk-free rate.
A12: Max Drawdown (heuristic) | B12: =-MIN(0.85,(1.8+1.4*(SUM('Look-through Exposures'!C2:C9)+'Look-through Exposures'!C13+'Look-through Exposures'!C14))*SQRT(MAX(SUMPRODUCT('Look-through Exposures'!C2:C14,MMULT(_Covariance!B2:N14,'Look-through Exposures'!C2:C14)),0))) -> -0.25354864 | C12: − min(0.85, (1.8 + 1.4·equityShare)·σ_p). For path-based MDD see the MC tab in the live app.
A13: Beta (vs ACWI) | B13: =IF(SUMPRODUCT('Look-through Exposures'!F2:F14,MMULT(_Covariance!B2:N14,'Look-through Exposures'!F2:F14))>0,SUMPRODUCT('Look-through Exposures'!C2:C14,MMULT(_Covariance!B2:N14,'Look-through Exposures'!F2:F14))/SUMPRODUCT('Look-through Exposures'!F2:F14,MMULT(_Covariance!B2:N14,'Look-through Exposures'!F2:F14)),0) -> 0.60370311 | C13: Cov(p,B) / Var(B). ACWI proxy = 60/14/4/4/4/14 across US/EU/UK/CH/JP/EM.
A14: Alpha (p.a. vs ACWI) | B14: =(SUMPRODUCT('Look-through Exposures'!C2:C14,'Look-through Exposures'!E2:E14))-('CMA Assumptions'!F2+(IF(SUMPRODUCT('Look-through Exposures'!F2:F14,MMULT(_Covariance!B2:N14,'Look-through Exposures'!F2:F14))>0,SUMPRODUCT('Look-through Exposures'!C2:C14,MMULT(_Covariance!B2:N14,'Look-through Exposures'!F2:F14))/SUMPRODUCT('Look-through Exposures'!F2:F14,MMULT(_Covariance!B2:N14,'Look-through Exposures'!F2:F14)),0))*(SUMPRODUCT('Look-through Exposures'!F2:F14,'Look-through Exposures'!E2:E14)-'CMA Assumptions'!F2)) -> 0.011225382 | C14: μ_p − [Rf + β · (μ_B − Rf)]. Uses net (post-WHT) returns on both sides.
A15: Tracking Error (p.a.) | B15: =SQRT(MAX(SUMPRODUCT('Look-through Exposures'!C2:C14,MMULT(_Covariance!B2:N14,'Look-through Exposures'!C2:C14))+SUMPRODUCT('Look-through Exposures'!F2:F14,MMULT(_Covariance!B2:N14,'Look-through Exposures'!F2:F14))-2*SUMPRODUCT('Look-through Exposures'!C2:C14,MMULT(_Covariance!B2:N14,'Look-through Exposures'!F2:F14)),0)) -> 0.0655297 | C15: √(Var_p + Var_B − 2·Cov(p,B)) — stdev of the active return.
A16: Outperformance (vs ACWI p.a.) | B16: =SUMPRODUCT('Look-through Exposures'!C2:C14,'Look-through Exposures'!E2:E14)-SUMPRODUCT('Look-through Exposures'!F2:F14,'Look-through Exposures'!E2:E14) -> -0.014533916 | C16: μ_p − μ_B (both net of WHT).

Sheet Parameters
A1: Snapshot
A2: Generated on | B2: 2026-05-12
A3: Source app | B3: Investment Decision Lab (artifacts/investment-lab)
A5: Default form values
A6: Base currency | B6: CHF
A7: Risk appetite | B7: High
A8: Horizon (years) | B8: 10
A9: Target equity % | B9: 60%
A10: Number of ETFs | B10: 10
A11: Preferred exchange | B11: SIX
A12: Thematic preference | B12: None
A13: Currency hedging | B13: off
A14: Synthetic ETFs | B14: off
A15: Look-through view | B15: on
A16: Crypto | B16: off
A17: Listed real estate | B17: off
A18: Commodities (Gold) | B18: on
A20: Risk-free rates (active = built-in ⊕ app-defaults.json)
A21: Rf USD | B21: 0.0425 | C21: built-in only
A22: Rf EUR | B22: 0.03 | C22: from app-defaults.json
A23: Rf GBP | B23: 0.049 | C23: from app-defaults.json
A24: Rf CHF | B24: 0.004 | C24: from app-defaults.json
A26: Home-bias factors
A27: Home bias USD | B27: 1 | C27: multiplier on home-region anchor
A28: Home bias EUR | B28: 1.5 | C28: multiplier on home-region anchor
A29: Home bias GBP | B29: 1.5 | C29: multiplier on home-region anchor
A30: Home bias CHF | B30: 2.5 | C30: multiplier on home-region anchor
A32: Equity-region cap constants
A33: Per-region cap | B33: 65% | C33: EQUITY_REGION_CAP
A34: MCAP anchor (CHF) — USA | B34: 60%
A35: MCAP anchor (CHF) — Europe | B35: 10%
A36: MCAP anchor (CHF) — Switzerland | B36: 4%
A37: MCAP anchor (CHF) — Japan | B37: 5%
A38: MCAP anchor (CHF) — EM | B38: 11%
A40: Benchmark (MSCI ACWI proxy used for α / β)
A41: US Equity | B41: 0.6 | C41: equity_us
A42: Europe Equity | B42: 0.14 | C42: equity_eu
A43: UK Equity | B43: 0.04 | C43: equity_uk
A44: Swiss Equity | B44: 0.04 | C44: equity_ch
A45: Japan Equity | B45: 0.04 | C45: equity_jp
...
